Workbook

Sheet Timeline 
B1: Januar | E1: Februar | AG1: Marts
A2: Task | B2: 29 | C2: 30 | D2: 31 | E2: 1 | F2: 2 | G2: 3 | H2: 4 | I2: 5 | J2: 6 | K2: 7 | L2: 8 | M2: 9 | N2: 10 | O2: 11 | P2: 12 | Q2: 13 | R2: 14 | S2: 15 | T2: 16 | U2: 17 | V2: 18 | W2: 19 | X2: 20 | Y2: 21 | Z2: 22 | AA2: 23 | AB2: 24 | AC2: 25 | AD2: 26 | AE2: 27 | AF2: 28 | AG2: 1 | AH2: 2 | AI2: 3 | AJ2: 4 | AK2: 5 | AL2: 6
A3: Write findings/topics from reviewed papers | AF3: FINAL | AL3: deadline
A4: Snowballing
A5: Structure
A6: Methodology (Lead)
A7: Distributed Writing
A8: Discussion
A9: Conclusion
A10: Introduction
A11: Refinement / Alignment (Figures, text, tables,...)
A12: Professors reviews
A13: Polishing
A14: Planning & Status Meeting Teams | F14: M | J14: M | N14: M | Q14: M | U14: M | X14: M | AB14: M | AD14: M | AE14: M | AH14: M | AJ14: M | AK14: M
A15: Legend:
A16: P = Planned / Expected
A17: D = Delayed
A18: Done = Completed
A19: X = Extended

Sheet RQs
A1: Group 1
A2: What existing decision support methods has had the biggest improvements in manufacturing?
A3: Where specifically are these improvements found and measured?
A4: In industry 4.0 related technologies, which are most widespread for current decision support improvements in manufacturing?
A6: Group 2
A7: Which decision problems are addressed by decision support approaches in HMLV manufacturing, and which problem characteristics are reported as challenging? (dynamic environment, random arrivals of jobs, real-time, large-scale/scalability).
A8: Which methods and enabling technologies are used for decision support in HMLV manufacturing systems?
A9: What decision objectives does decision support in HMLV manufacturing have? (makespan, energy consumption, ...)
A10: How are decision support approaches for HMLV manufacturing evaluated, and what limitations are reported regarding their applicability and deployment?
A12: Group 3
A13: Are there similarities between decision-support tools stemming from different levels of production?
A14: What is the most common area/subject tackled in decision-support in HMLV?
... A24: Decision objective: Makespan, energy consumption, robustness/resilience

Sheet Info
A1: L0 | B1: Machine/Process level - A single machine, workstation and process. Such as an CNC machine.
A2: L1 | B2: Line/Cell level - A group of machines or processes that interact. An example could be a manufacturing cell with two robots and two CNC machines.
A3: L2 | B3: Factory level - An entire factory consisting of multiple lines or cells, or where the paper is concerned with a group of machines.
A4: L3/L4 | B4: Enterprise/Supply chain - Multiple factories/plants or external partners across a supply chain.
A6: Claimed contribution vs actual contribution | B6: What I had in mind was the following: The claimed contribution is what the authors of the paper claim their contribution to be. This is often mentioned in the abstract, put in bullets in the end of the introduction, hopefully address during the discussion, and lastly touch upon in the conclusion. However, authors do unfortunately occasionally over sell their contributions and/or fail to highlight what is the main takeaway from the paper (so it can be ‘bad’ in both directions). Hence, I often note what I think is the actual contribution of the paper. Naturally, for a good peer-review paper the claimed contribution and what you think is a contribution should align almost exactly.
B7: For example, some papers only evaluate their performance in a very limited set of scenarios
B8: Or stating three contributions where two of them are roughly the same but rephrased slightly different to get a total of three contributions (which for some reason looks better…. or something..)

Sheet Master sheet
A1: key_id | B1: Title | C1: Relevance Score | D1: Reasoning | E1: Methods | F1: Technologies | G1: Automated Manufacturing Level | H1: Negatives Found | I1: Manfufacturing level | J1: Reviewer | K1: Snowball? | L1: Reviewer Suggested | M1: Page count | N1: L0 Count | O1: L1 Count | P1: L2 Count | Q1: L3 Count | R1: L4 Count | S1: L3/L4 Count | T1: L0/L1/L2/L3/L4 | U1: Count All | V1: Filtered L0 Count | W1: Filtered L1 Count | X1: Filtered L2 Count | Y1: Filtered L3 Count | Z1: Filtered L4 Count | AA1: Filtered L3/L4 Count | AB1: Filtered L0/L1/L2/L3/L4 Count | AC1: All filtered count
A2: 2024_unleashing_mixed-reality_capability_in_deep_reinforcement_learning-based_robot_motion_generation_towards_safe_human–robot_collaboration | B2: Unleashing mixed-reality capability in Deep Reinforcement Learning-based robot motion generation towards safe human–robot collaboration | C2: ++ | D2: Core tech (19) + manufacturing (6) + strong decision or scheduling/simulation/robotics signal | E2: reinforcement learning, simulation | F2: deep learning, human-robot collaboration, reinforcement learning, robot | G2: Unclassified | I2: L0 | J2: P5 | N2: =COUNTIF($I$1:$I$250,"L0") -> 9 | O2: =COUNTIF($I$1:$I$250,"L1") -> 11 | P2: =COUNTIF($I$1:$I$250,"L2") -> 102 | Q2: =COUNTIF($I$1:$I$250,"L3") -> 6 | R2: =COUNTIF($I$1:$I$250,"L4") -> 10 | S2: =COUNTIF($I$1:$I$250,"L3/L4") -> 0 | T2: =COUNTIF($I$1:$I$250,"L0/L1/L2/L3/L4") -> 2 | U2: =N2+O2+P2+S2+T2 -> 124 | V2: =N2 -> 9 | W2: =O2-1 -> 10 | X2: =P2-4 -> 98 | Y2: =Q2-0 -> 6 | Z2: =R2-2 -> 8 | AA2: =S2 -> 0 | AB2: =T2 -> 2 | AC2: =V2+W2+X2+AA2+AB2 -> 119
A3: 2024_rtmn_2.0—an_extension_of_robot_task_modeling_and_notation_(rtmn)_focused_on_human–robot_collaboration | B3: RTMN 2.0—An Extension of Robot Task Modeling and Notation (RTMN) Focused on Human–Robot Collaboration | C3: ++ | D3: Core tech (17) + manufacturing (4) + strong decision or scheduling/simulation/robotics signal | F3: hrc, robot | G3: Unclassified | I3: L0 | J3: P5
A4: 2024_design_and_optimization_of_smt_reflow_soldering_curves_driven_by_digital_twins | B4: Design and Optimization of SMT Reflow Soldering Curves Driven by Digital Twins | C4: ++ | D4: Core tech (4) + manufacturing (2) + strong decision or scheduling/simulation/robotics signal | E4: optimization | F4: digital twin | G4: Unclassified | I4: L0 | J4: P5
A5: 2023_knowledge-driven_framework_for_industrial_robotic_systems | B5: Knowledge-driven framework for industrial robotic systems | C5: ++ | D5: Core tech (7) + manufacturing (2) + strong decision or scheduling/simulation/robotics signal | F5: robot, robotics | G5: Unclassified | I5: L0 | J5: P5
A6: 2022_towards_data-driven_additive_manufacturing_processes | B6: Towards data-driven additive manufacturing processes | C6: ++ | D6: Core tech (3) + manufacturing (6) + strong decision or scheduling/simulation/robotics signal | F6: data driven, data-driven | G6: Unclassified | I6: L0 | J6: P5
A7: 2022_applied_reinforcement_learning_for_decision_making_in_industrial_simulation_environments | B7: Applied Reinforcement Learning for Decision Making in Industrial Simulation Environments | C7: ++ | D7: Core tech (6) + manufacturing (1) + strong decision or scheduling/simulation/robotics signal | E7: reinforcement learning, simulation | F7: artificial intelligence, machine learning, reinforcement learning | G7: Factory | I7: L0 | J7: P5
A8: 2022_toward_a_collaborative_sensor_network_integration_for_smes’_zero-defect_manufacturing | B8: Toward a Collaborative Sensor Network Integration for SMEs’ Zero-Defect Manufacturing | C8: ++ | D8: Core tech (6) + manufacturing (8) + strong decision or scheduling/simulation/robotics signal | F8: artificial intelligence, cpps, cyber-physical production systems, iiot, internet of things | G8: Unclassified | I8: L0 | J8: P5
A9: 2021_digital_twin_as_a_tool_to_select_ct_scan_parameters | B9: Digital Twin as a Tool to Select CT Scan Parameters | C9: ++ | D9: Core tech (3) + manufacturing (4) + strong decision or scheduling/simulation/robotics signal | F9: digital twin | G9: Unclassified | I9: L0 | J9: P5
A10: 2019_an_energy-aware_multiobjective_optimization_framework_to_minimize_total_tardiness_and_energy_cost_on_a_single-machine_nonpreemptive_scheduling | B10: An Energy-Aware Multiobjective Optimization Framework to Minimize Total Tardiness and Energy Cost on a Single-Machine Nonpreemptive Scheduling | C10: ++ | D10: Core tech (3) + manufacturing (7) + strong decision or scheduling/simulation/robotics signal | E10: genetic algorithm, optimization | F10: internet of things | G10: Factory | H10: Managerial/business/policy focus | I10: L0 | J10: P5
A11: 2024_balancing_heterogeneous_assembly_line_with_multi-skilled_human-robot_collaboration_via_adaptive_cooperative_co-evolutionary_algorithm | B11: Balancing heterogeneous assembly line with multi-skilled human-robot collaboration via Adaptive cooperative co-evolutionary algorithm | C11: ++ | D11: Core tech (12) + manufacturing (3) + strong decision or scheduling/simulation/robotics signal | E11: evolutionary algorithm, metaheuristic, q-learning, reinforcement learning | F11: cobots, hrc, human-robot collaboration, reinforcement learning, robot | G11: Factory | I11: L1 | J11: P5
A12: 2024_data-driven_simulation-based_decision_support_system_for_resource_allocation_in_industry_4.0_and_smart_manufacturing | B12: Data-driven simulation-based decision support system for resource allocation in industry 4.0 and smart manufacturing | C12: ++ | D12: Core tech (5) + manufacturing (10) + strong decision or scheduling/simulation/robotics signal | E12: optimization, simulation | F12: artificial intelligence, data-driven | G12: Unclassified | I12: L1 | J12: P5
A13: 2024_deep_reinforcement_learning_with_a_look-ahead_search_for_robotic_cell_scheduling | B13: Deep Reinforcement Learning With a Look-Ahead Search for Robotic Cell Scheduling | C13: ++ | D13: Core tech (9) + manufacturing (7) + strong decision or scheduling/simulation/robotics signal | E13: reinforcement learning | F13: deep learning, reinforcement learning, robot | G13: Factory | I13: L1 | J13: P5
A14: 2024_power_consumption_and_process_cost_prediction_of_customized_products_using_explainable_ai:_a_case_in_the_steel_industry | B14: Power Consumption and Process Cost Prediction of Customized Products Using Explainable AI: A Case in the Steel Industry | C14: ++ | D14: Core tech (9) + manufacturing (7) + strong decision or scheduling/simulation/robotics signal | E14: forecasting, random forest | F14: artificial intelligence, data driven, data-driven, machine learning | G14: Unclassified | I14: L1 | J14: P5
A15: 2023_versatile_information_provisioning_in_a_configure-to-order_production_environment;_a_case_study | B15: Versatile information provisioning in a configure-to-order production environment; a case study | C15: ++ | D15: Core tech (4) + manufacturing (1) + strong decision or scheduling/simulation/robotics signal | F15: digital twin, iot, robot | G15: Unclassified | I15: L1 | J15: P5
A16: 2023_implementation_scheme_and_research_of_iot_electronic_"intelligent_manufacturing"_based_on_mes_system | B16: Implementation Scheme and Research of IoT Electronic "intelligent Manufacturing" Based on MES System | C16: ++ | D16: Core tech (5) + manufacturing (21) + strong decision or scheduling/simulation/robotics signal | F16: internet of things, iot | G16: Unclassified | I16: L1 | J16: P5
A17: 2022_production_task_allocation_decision_based_on_cloud_robot_cell-line | B17: Production Task Allocation Decision Based on Cloud Robot Cell-Line | C17: ++ | D17: Core tech (8) + manufacturing (11) + strong decision or scheduling/simulation/robotics signal | E17: optimization | F17: internet of things, robot, robotics | G17: Factory | I17: L1 | J17: P5
A18: 2021_monte_carlo_tree_search_for_online_decision_making_in_smart_industrial_production | B18: Monte Carlo Tree Search for online decision making in smart industrial production | C18: ++ | D18: Core tech (4) + manufacturing (1) + strong decision or scheduling/simulation/robotics signal | E18: simulation | F18: hrc, human-robot collaboration | G18: Unclassified | I18: L1 | J18: P5
A19: 2020_computer_vision-enabled_hcps_assembly_workstations_swarm_for_enhancing_responsiveness_in_mass_customization | B19: Computer Vision-enabled HCPS Assembly Workstations Swarm for Enhancing Responsiveness in Mass Customization | C19: ++ | D19: Core tech (4) + manufacturing (4) + strong decision or scheduling/simulation/robotics signal | F19: cyber-physical system, robot, robotics | G19: Unclassified | I19: L1 | J19: P5
A20: 2019_multiagent_using_solving_the_job_scheduling_problem_in_the_industry_4.0 | B20: Multiagent using solving the job scheduling problem in the industry 4.0 | C20: ++ | D20: Core tech (5) + manufacturing (3) + strong decision or scheduling/simulation/robotics signal | E20: simulation | F20: cps, internet of things, iot | G20: Factory | I20: L1 | J20: P5
A21: 2018_mobile_robot_scheduling_for_cycle_time_optimization_in_flow-shop_cells,_a_case_study | B21: Mobile robot scheduling for cycle time optimization in flow-shop cells, a case study | C21: ++ | D21: Core tech (11) + manufacturing (7) + strong decision or scheduling/simulation/robotics signal | E21: metaheuristic, optimization | F21: robot | G21: Factory | H21: Managerial/business/policy focus | I21: L1 | J21: P5
A22: 2024_transitioning_trends_into_action:_a_simulation-based_digital_twin_architecture_for_enhanced_strategic_and_operational_decision-making | B22: Transitioning trends into action: A simulation-based Digital Twin architecture for enhanced strategic and operational decision-making | C22: ++ | D22: Core tech (5) + manufacturing (7) + strong decision or scheduling/simulation/robotics signal | E22: simulation | F22: artificial intelligence, digital twin, robotics | G22: Factory | I22: L2 | J22: P2
A23: 2024_learning-enabled_flexible_job-shop_scheduling_for_scalable_smart_manufacturing | B23: Learning-enabled flexible job-shop scheduling for scalable smart manufacturing | C23: ++ | D23: Core tech (5) + manufacturing (7) + strong decision or scheduling/simulation/robotics signal | E23: reinforcement learning | F23: agvs, reinforcement learning | G23: Factory | I23: L2 | J23: P2
A24: 2024_a_deep_reinforcement_learning_based_approach_for_dynamic_job_shop_scheduling_considering_variable_processing_time | B24: A deep reinforcement learning based approach for dynamic job shop scheduling considering variable processing time | C24: ++ | D24: Core tech (6) + manufacturing (10) + strong decision or scheduling/simulation/robotics signal | E24: genetic algorithm, markov decision process, reinforcement learning | F24: deep learning, reinforcement learning | G24: Factory | I24: L2 | J24: P2
A25: 2024_a_machine_learning-based_simulation_metamodeling_method_for_dynamic_scheduling_in_smart_manufacturing_systems | B25: A machine learning-based simulation metamodeling method for dynamic scheduling in smart manufacturing systems | C25: ++ | D25: Core tech (4) + manufacturing (12) + strong decision or scheduling/simulation/robotics signal | E25: boosting, simulation | F25: digital twin, machine learning | G25: Factory | I25: L2 | J25: P2
A26: 2024_two-stage_double_deep_q-network_algorithm_considering_external_non-dominant_set_for_multi-objective_dynamic_flexible_job_shop_scheduling_problems | B26: Two-stage double deep Q-network algorithm considering external non-dominant set for multi-objective dynamic flexible job shop scheduling problems | C26: ++ | D26: Core tech (6) + manufacturing (9) + strong decision or scheduling/simulation/robotics signal | E26: deep q-network, optimization, reinforcement learning | F26: deep learning, reinforcement learning | G26: Factory | I26: L2 | J26: P2
A27: 2024_optimizing_industrial_maintenance_scheduling_through_deep_reinforcement_learning_and_simulation_integration | B27: Optimizing Industrial Maintenance Scheduling Through Deep Reinforcement Learning and Simulation Integration | C27: ++ | D27: Core tech (4) + manufacturing (6) + strong decision or scheduling/simulation/robotics signal | E27: reinforcement learning, simulation | F27: reinforcement learning | G27: Factory | I27: L2 | J27: P2
A28: 2024_a_recurrent_reinforcement_learning_strategy_for_optimal_scheduling_of_partially_observable_job-shop_and_flow-shop_batch_chemical_plants_under_uncertainty | B28: A recurrent reinforcement learning strategy for optimal scheduling of partially observable job-shop and flow-shop batch chemical plants under uncertainty | C28: ++ | D28: Core tech (4) + manufacturing (1) + strong decision or scheduling/simulation/robotics signal | E28: q-learning, reinforcement learning | F28: deep learning, reinforcement learning | G28: Factory | I28: L2 | J28: P2
A29: 2024_machine_learning_prediction_model_for_dynamic_scheduling_of_hybrid_flow-shop_based_on_metaheuristic | B29: Machine Learning prediction model for Dynamic Scheduling of Hybrid Flow-Shop based on Metaheuristic | C29: ++ | D29: Core tech (2) + manufacturing (7) + strong decision or scheduling/simulation/robotics signal | E29: genetic algorithm, metaheuristic, optimization | F29: machine learning | G29: Factory | I29: L2 | J29: P2
A30: 2024_rainbow_versus_deep_q-network:_a_reinforcement_learning_comparison_on_the_flexible_job-shop_problem | B30: Rainbow Versus Deep Q-Network: A Reinforcement Learning Comparison on the Flexible Job-Shop Problem | C30: ++ | D30: Core tech (6) + manufacturing (1) + strong decision or scheduling/simulation/robotics signal | E30: deep q-network, dqn, optimization, reinforcement learning | F30: reinforcement learning | G30: Factory | H30: Managerial/business/policy focus | I30: L2 | J30: P2
A31: 2024_"smart"_lead_time_prediction_in_smes_environments:_a_theoretical_framework_proposal | B31: "smart" Lead Time Prediction in SMEs environments: A theoretical framework proposal | C31: ++ | D31: Core tech (2) + manufacturing (6) + strong decision or scheduling/simulation/robotics signal | E31: forecasting | F31: analytics | G31: Unclassified | I31: L2 | J31: P2
A32: 2024_solving_flexible_job-shop_scheduling_problem_with_heterogeneous_graph_neural_network_based_on_relation_and_deep_reinforcement_learning | B32: Solving Flexible Job-Shop Scheduling Problem with Heterogeneous Graph Neural Network Based on Relation and Deep Reinforcement Learning | C32: ++ | D32: Core tech (5) + manufacturing (3) + strong decision or scheduling/simulation/robotics signal | E32: attention mechanism, feature extraction, graph neural network, optimization, ppo, reinforcement learning | F32: neural network, reinforcement learning | G32: Factory | I32: L2 | J32: P2
A33: 2024_the_use_of_reinforcement_learning_for_material_flow_control:_an_assessment_by_simulation | B33: The use of reinforcement learning for material flow control: An assessment by simulation | C33: ++ | D33: Core tech (5) + manufacturing (8) + strong decision or scheduling/simulation/robotics signal | E33: reinforcement learning, simulation | F33: reinforcement learning | G33: Factory | I33: L2 | J33: P2
A34: 2024_smart_scheduling_of_dynamic_job_shop_based_on_discrete_event_simulation_and_deep_reinforcement_learning | B34: Smart scheduling of dynamic job shop based on discrete event simulation and deep reinforcement learning | C34: ++ | D34: Core tech (6) + manufacturing (7) + strong decision or scheduling/simulation/robotics signal | E34: optimization, ppo, reinforcement learning, simulation | F34: deep learning, reinforcement learning | G34: Factory | I34: L2 | J34: P2
A35: 2024_fast_pareto_set_approximation_for_multi-objective_flexible_job_shop_scheduling_via_parallel_preference-conditioned_graph_reinforcement_learning | B35: Fast Pareto set approximation for multi-objective flexible job shop scheduling via parallel preference-conditioned graph reinforcement learning | C35: ++ | D35: Core tech (7) + manufacturing (7) + strong decision or scheduling/simulation/robotics signal | E35: evolutionary algorithm, graph neural network, reinforcement learning | F35: deep learning, neural network, reinforcement learning | G35: Factory | I35: L2 | J35: P2
A36: 2024_a_double_deep_q-network_framework_for_a_flexible_job_shop_scheduling_problem_with_dynamic_job_arrivals_and_urgent_job_insertions | B36: A Double Deep Q-Network framework for a flexible job shop scheduling problem with dynamic job arrivals and urgent job insertions | C36: ++ | D36: Core tech (3) + manufacturing (10) + strong decision or scheduling/simulation/robotics signal | E36: deep q-network, optimization, q-learning, reinforcement learning, simulation | F36: deep learning, reinforcement learning | G36: Factory | I36: L2 | J36: P2
A37: 2024_introducing_petrirl:_an_innovative_framework_for_jssp_resolution_integrating_petri_nets_and_event-based_reinforcement_learning | B37: Introducing PetriRL: An innovative framework for JSSP resolution integrating Petri nets and event-based reinforcement learning | C37: ++ | D37: Core tech (5) + manufacturing (7) + strong decision or scheduling/simulation/robotics signal | E37: optimization, ppo, reinforcement learning, simulation | F37: deep learning, reinforcement learning | G37: Factory | I37: L2 | J37: P2
A38: 2024_multi-agent_reinforcement_learning_for_job_shop_scheduling_in_dynamic_environments | B38: Multi-Agent Reinforcement Learning for Job Shop Scheduling in Dynamic Environments | C38: ++ | D38: Core tech (7) + manufacturing (6) + strong decision or scheduling/simulation/robotics signal | E38: graph neural network, multi-agent reinforcement learning, optimization, reinforcement learning | F38: machine learning, neural network, reinforcement learning | G38: Factory | I38: L2 | J38: P2
A39: 2024_an_end-to-end_deep_reinforcement_learning_method_based_on_graph_neural_network_for_distributed_job-shop_scheduling_problem | B39: An end-to-end deep reinforcement learning method based on graph neural network for distributed job-shop scheduling problem | C39: ++ | D39: Core tech (8) + manufacturing (7) + strong decision or scheduling/simulation/robotics signal | E39: feature extraction, gnn, graph neural network, markov decision process, mdp, optimization, ppo, reinforcement learning | F39: deep learning, neural network, reinforcement learning | G39: Factory | I39: L2 | J39: P2
A40: 2024_job_shop_smart_manufacturing_scheduling_by_deep_reinforcement_learning | B40: Job shop smart manufacturing scheduling by deep reinforcement learning | C40: ++ | D40: Core tech (8) + manufacturing (16) + strong decision or scheduling/simulation/robotics signal | E40: markov decision process, mdp, ppo, reinforcement learning | F40: deep learning, digital twin, reinforcement learning | G40: Factory | I40: L2 | J40: P2
...

Sheet Cleaned Master sheet
B1: key_id | C1: Title | D1: DOI | E1: Snowball (Yes/No) | F1: Manufacturing level (L0,L1,L2,L3/L4) | G1: Old Evaluation (Scenarios, Simulation, Case study,…) | H1: Primary Evaluation(s) | I1: Evaluation setting | J1: Data Source | K1: Technologies | L1: Methods | M1: Country | N1: Date | O1: Industry | P1: DSS focus | Q1: Job-shop variations | R1: Metrics | S1: Improvement goals or objectives (What they try to achieve) | T1: comments | U1: Bibtex ref | V1: Cited in survey? Yes/No | W1: Special/different papers notes for discussion
A2: P1 | B2: 2022_demonstration_of_the_feasibility_of_real_time_application_of_machine_learning_to_production_scheduling | C2: Demonstration of the Feasibility of Real Time Application of Machine Learning to Production Scheduling | D2: https://doi.org/10.1109/WSC57314.2022.10015436 | E2: No | F2: L2 | G2: Industrial Case study | H2: Offline industrial | I2: static evaluation | J2: Industrial data | K2: ML, MES | L2: Optimisation | M2: Netherlands | N2: 2022 | O2: Semiconductor | P2: Scheduling | Q2: No | R2: makespan minisation | S2: Improved scheduling of wafer production | U2: Ghasemi2022Demonstration | V2: Yes
A3: P1 | B3: 2022_using_a_systems_approach_to_model_a_process_digital_twin | C3: Using a systems approach to model a process digital twin | D3: https://doi.org/10.1016/j.ifacol.2022.09.677 | E3: No | F3: L2 | G3: Indutrial Case study | H3: Indutrial Case study | I3: industrial case study | J3: Industrial data | K3: DT | L3: Optimisation | M3: Netherlands | N3: 2022 | O3: Metal & machining | P3: Lead time prediction | Q3: No | R3: Tardiness | S3: improved planning and control | U3: Herkes2022Using | V3: Yes
A4: P1 | B4: 2022_predicting_makespan_in_flexible_job_shop_scheduling_problem_using_machine_learning | C4: Predicting makespan in Flexible Job Shop Scheduling Problem using Machine Learning | D4: https://doi.org/10.1016/j.ifacol.2022.09.305 | E4: No | F4: L2 | G4: scenario | I4: static evaluation | J4: synthetic | K4: ML, AI | L4: Random Forest | M4: France | N4: 2022 | O4: Not specified | P4: Scheduling | Q4: Flexible Job Shop Scheduling | R4: Makespan minimisation | S4: Predict production plan feasibility | U4: Tremblet2022Predicting | V4: Yes
A5: P1 | B5: 2022_a_dynamic_programming-based_heuristic_algorithm_for_a_flexible_job_shop_scheduling_problem_of_a_matrix_system_in_automotive_industry | C5: A dynamic programming-based heuristic algorithm for a flexible job shop scheduling problem of a matrix system in automotive industry | D5: https://doi.org/10.1109/CASE49997.2022.9926440 | E5: No | F5: L2 | G5: Simulation | I5: simulation | J5: synthetic+industrial data | L5: MDP, Heuristic | M5: South Korea | N5: 2022 | O5: Automotive | P5: Scheduling | Q5: Flexible Job Shop Scheduling | R5: Makespan minimisation | S5: AMR routing optimisation in an FJSSP | U5: Kim2022A | V5: Yes
A6: P1 | B6: 2022_deep_reinforcement_learning-based_job_shop_scheduling_of_smart_manufacturing | C6: Deep Reinforcement Learning-Based Job Shop Scheduling of Smart Manufacturing | D6: https://doi.org/10.32604/cmc.2022.030803 | E6: No | F6: L2 | G6: Illustrative Case study+Benchmark | H6: static evaluation | I6: simulation | J6: benchmark data (ft06, ft10 (Fisher); (Applegate & Cook); (Lawrence)) | K6: RL | L6: GNN, MDP | M6: Egypt | N6: 2022 | O6: Not specified | P6: Scheduling | Q6: Job Shop Scheduling | R6: Makespan minimisation | S6: Finding the optimal scheduling policy | U6: ElSayed2022Deep | V6: Yes
A7: P1 | B7: 2022_scalability_investigation_of_double_deep_q_learning_for_factory_layout_planning | C7: Scalability investigation of Double Deep Q Learning for factory layout planning | D7: https://doi.org/10.1016/j.procir.2022.04.027 | E7: No | F7: L2 | G7: Scenario | H7: static evaluation | I7: simulation | J7: Synthetic | K7: RL | L7: DQN | M7: Germany | N7: 2022 | O7: Not specified | P7: Plant layout | Q7: No | R7: Machine utilisation | S7: Optimising scheduling based on total distance traveled | U7: Klar2022Scalability | V7: Yes
A8: P1 | B8: 2022_predictive_maintenance_decision_making_based_on_reinforcement_learning_in_multistage_production_systems | C8: Predictive Maintenance Decision Making Based on Reinforcement Learning in Multistage Production Systems | D8: https://doi.org/10.1109/ACCESS.2022.3151170 | E8: No | F8: L2 | G8: Simulation | I8: simulation | J8: synthetic | K8: RL | L8: Predictive Maintenance | M8: China | N8: 2022 | O8: Not specified | P8: Predictive maintenance | Q8: No | R8: Tardiness | S8: finding the best predictive maintenance model | U8: Feng2022Predictive | V8: YesNo
A9: P1 | B9: 2022_simultaneous_part_input_sequencing_and_robot_scheduling_for_mass_customisation | C9: Simultaneous part input sequencing and robot scheduling for mass customisation | D9: https://doi.org/10.1080/00207543.2021.1894369 | E9: No | F9: L2 | G9: Simulation | I9: simulation | J9: synthetic | K9: FMS | L9: Heuristic | M9: China | N9: 2022 | O9: Semiconductor | P9: Scheduling | Q9: No | R9: Machine utilisation | S9: Optimsing simultaneous part input sequencing and robot scheduling | U9: He2022Simultaneous | V9: Yes
A10: P1 | B10: 2021_multi-agent_reinforcement_learning_for_online_scheduling_in_smart_factories | C10: Multi-agent reinforcement learning for online scheduling in smart factories | D10: https://doi.org/10.1016/j.rcim.2021.102202 | E10: No | F10: L2 | G10: lab case study | I10: lab case study | J10: lab data | K10: CPS, IoT, RL | L10: MARL | M10: China | N10: 2021 | O10: Not specified | P10: Scheduling | Q10: No | R10: Makespan minimisation | S10: Improved Scheduling | U10: Zhou2021Multiagent | V10: Yes
A11: P1 | B11: 2021_data-driven_dispatching_rules_mining_and_real-time_decision-making_methodology_in_intelligent_manufacturing_shop_floor_with_uncertainty | C11: Data-driven dispatching rules mining and real-time decision-making methodology in intelligent manufacturing shop floor with uncertainty | D11: https://doi.org/10.3390/s21144836 | E11: No | F11: L2 | G11: Simulation+Sensitivity analysis | I11: simulation | J11: synthetic | K11: ML, CPS | M11: China | N11: 2021 | O11: Not specified | P11: Scheduling | Q11: Job Shop Scheduling | R11: Makespan & Tardiness | S11: Improved scheduling | U11: Zhang2021Datadriven | V11: Yes
A12: P1 | B12: 2021_evolutionary_game_based_real-time_scheduling_for_energy-efficient_distributed_and_flexible_job_shop | C12: Evolutionary game based real-time scheduling for energy-efficient distributed and flexible job shop | D12: https://doi.org/10.1016/j.jclepro.2021.126093 | E12: No | F12: L2 | G12: Industrial Case study+scenario+Simulation | H12: simulation | I12: simulation | J12: synthetic+industrial data | K12: IoT, Edge Computing | M12: China | N12: 2021 | O12: Automotive | P12: Scheduling | Q12: Flexible Job Shop Scheduling | R12: Makespan | S12: improved scheduling | U12: Wang2021Evolutionary | V12: Yes
A13: P1 | B13: 2021_artificial-intelligence-driven_customized_manufacturing_factory:_key_technologies,_applications,_and_challenges | C13: Artificial-Intelligence-Driven Customized Manufacturing Factory: Key Technologies, Applications, and Challenges | D13: https://doi.org/10.1109/JPROC.2020.3034808 | E13: No | F13: L2 | G13: lab Case study | I13: lab case study | J13: lab data | K13: CPS, IoT, Edge Computing, Cloud | M13: China | N13: 2021 | O13: Food packaging | P13: Scheduling | Q13: No | R13: N/A | S13: Exploring AI in customised manufacturing | U13: Wan2021ArtificialIntelligenceDriven | V13: Yes
A14: P1 | B14: 2021_a_prescriptive_maintenance_system_for_intelligent_production_planning_and_control_in_a_smart_cyber-physical_production_line | C14: A prescriptive maintenance system for intelligent production planning and control in a smart cyber-physical production line | D14: https://doi.org/10.1016/j.procir.2021.11.307 | E14: No | F14: L2 | G14: Industrial Case study+simulation | H14: simulation | I14: simulation | J14: industrial data+synthetic | K14: DT, RL | M14: Italy | N14: 2021 | O14: Metal & machining | P14: Scheduling | Q14: No | R14: N/A | S14: Developing prescriptive maintenance | U14: Padovano2021A | V14: Yes
A15: P1 | B15: 2021_reinforcement_learning_with_composite_rewards_for_production_scheduling_in_a_smart_factory | C15: Reinforcement Learning with Composite Rewards for Production Scheduling in a Smart Factory | D15: https://doi.org/10.1109/ACCESS.2020.3046784 | E15: No | F15: L2 | G15: indsutrial case study+simulation+scenarios | H15: lab case study | I15: simulation | J15: lab data | K15: RL | M15: China | N15: 2021 | O15: Not specified | P15: Scheduling | Q15: No | R15: Makespan minimisation | S15: Improved scheduling | U15: Zhou2021Reinforcement | V15: Yes
A16: P1 | B16: 2021_modeling_and_implementation_of_a_digital_twin_of_material_flows_based_on_physics_simulation | C16: Modeling and implementation of a digital twin of material flows based on physics simulation | D16: https://doi.org/10.1016/j.jmsy.2020.04.015 | E16: No | F16: L2 | G16: lab case study+simulation | I16: lab case study | J16: lab data | K16: DT, CPS, OPC UA | M16: Germany | N16: 2021 | O16: Not specified | P16: Safe materials transportation | Q16: No | R16: Makespan minimsation | S16: Develop digital twin enabled material handling system | U16: Glatt2021Modeling | V16: Yes
A17: P1 | B17: 2020_simulation_optimization_framework_for_online_deployment_and_adjustment_of_reconfigurable_machines_in_job_shops | C17: Simulation optimization framework for online deployment and adjustment of reconfigurable machines in job shops | D17: https://doi.org/10.1109/IEEM45057.2020.9309782 | E17: No | F17: L2 | G17: case study+simulation+scenarios | H17: simulation+scenarios | I17: simulation | J17: synthetic | K17: DT, RMS, CPS | L17: Optimisation, Simulation, Heuristic | M17: China | N17: 2020 | O17: Not specified | P17: Machine configurations | Q17: No | R17: Makespan minimisation? | S17: creating a real-time adjustment of reconfigurable or multi-functional machines DT | U17: Feng2020Simulation | V17: Yes
A18: P1 | B18: 2020_a_middleware_platform_for_intelligent_automation:_an_industrial_prototype_implementation | C18: A Middleware Platform for Intelligent Automation: An Industrial Prototype Implementation | D18: https://doi.org/10.1016/j.compind.2020.103329 | E18: No | F18: L2 | G18: lab case study | I18: lab case study | J18: lab data+industrial data | K18: CPS, IoT, AI, OPC UA, Edge Computing | M18: Portugal | N18: 2020 | O18: Pharmaceutical | P18: Interoperability | Q18: No | R18: Robustness --> delay rate, machine utilization rate, number of used machine, mean total waiting time (TWT) | S18: Proposing a platform providing real-time decision support | U18: Coito2020A | V18: Yes
A19: P1 | B19: 2025_uncertainty-aware_power_consumption_prediction_in_customized_stainless-steel_manufacturing:_a_comparative_study_of_hierarchical_bayesian_and_deep_neural_models | C19: Uncertainty-aware power consumption prediction in customized stainless-steel manufacturing: A comparative study of hierarchical Bayesian and deep neural models | D19: https://doi.org/10.1016/j.jmsy.2025.10.010 | E19: No | F19: L2 | G19: indsutrial case study | I19: static evaluation | J19: Industrial data | K19: RL | L19: Bayesian Learning | M19: Germany | N19: 2025 | O19: Metal & machining | P19: Power consumption | Q19: No | R19: Energy Efficiency | S19: Improved power prediction model for customised stainless-steel production | U19: Chawalitanont2025Uncertaintyaware | V19: YesNo
A20: P1 | B20: 2025_mamhsan:_a_multi-agent_deep_reinforcement_learning_framework_based_on_multi-head_self-attention_network_with_heterogeneous_graph_embedding_for_flexible_job_shop_scheduling | C20: MAMHSAN: A multi-agent deep reinforcement learning framework based on multi-head self-attention network with heterogeneous graph embedding for flexible job shop scheduling | D20: https://doi.org/10.1016/j.cie.2025.111466 | E20: No | F20: L2 | G20: benchmark+scenario | H20: static evaluation | I20: simulation | J20: synthetic+benchmark data Barnes, Brandimarte, Dauzere, and Hurink (edata, rdata, vdata) | K20: RL | L20: GNN | M20: China | N20: 2025 | O20: Not specified | P20: Scheduling | Q20: Flexible Job Shop Scheduling | R20: Makespan minimisation | S20: Improved scheduling | U20: Zhang2025MAMHSAN | V20: Yes
A21: P1 | B21: 2025_material_delivery_optimization_for_make-to-order_reconfigurable_job_shops_using_an_improved_chaotic_multi-verse_algorithm | C21: Material delivery optimization for make-to-order reconfigurable job shops using an improved chaotic multi-verse algorithm | D21: https://doi.org/10.1016/j.swevo.2025.102167 | E21: No | F21: L2 | G21: industrial case study+sensitivety analysis | H21: offline industrial | I21: simulation | J21: synthetic | K21: CPS | L21: Metaheuristic | M21: China | N21: 2025 | O21: Cylinder production | P21: Scheduling | Q21: Reconfigurable Job Shop Scheduling | R21: Makespan minimisation / Machine utilisation | S21: Improved AGV order delivery | U21: Xiao2025Material | V21: Yes
A22: P1 | B22: 2025_a_multi-trigger_mechanism_design_for_rescheduling_decision_assistance_in_smart_job_shops_based_on_machine_learning | C22: A Multi-Trigger Mechanism Design for Rescheduling Decision Assistance in Smart Job Shops Based on Machine Learning | D22: https://doi.org/10.3390/su17052198 | E22: No | F22: L2 | G22: industrial case study | H22: check | I22: simulation | J22: industrial data+synthetic | K22: ML, CPS | L22: Classification, Heuristic | M22: China | N22: 2025 | O22: Not specified | P22: Scheduling | Q22: Dynamic Job Shop Scheduling | R22: Robustness --> machine learning metrics: Confusion matrix, Accuracy, Precision, Recall, ROC curve, AUC | S22: Decision making on rescheduling timing and location | U22: Duan2025A | V22: Yes
A23: P1 | B23: 2025_dynamic_scheduling_for_multi-objective_flexible_job_shop_via_deep_reinforcement_learning | C23: Dynamic scheduling for multi-objective flexible job shop via deep reinforcement learning | D23: https://doi.org/10.1016/j.asoc.2025.112787 | E23: No | F23: L2 | G23: scenario | H23: static evaluation | I23: simulation | J23: synthetic+benchmark data (Not typically used). | K23: RL | L23: PPO | M23: China | N23: 2025 | O23: Not specified | P23: Scheduling | Q23: Dynamic flexible job shop scheduling | R23: Makespan | S23: Improved rescheduling for dynamic event handling | U23: Yuan2025Dynamic | V23: Yes
A24: P1 | B24: 2025_applying_decision_transformers_to_enhance_neural_local_search_on_the_job_shop_scheduling_problem | C24: Applying Decision Transformers to Enhance Neural Local Search on the Job Shop Scheduling Problem | D24: https://doi.org/10.3390/ai6030048 | E24: No | F24: L2 | G24: benchmark+scenario | I24: static evaluation | J24: synthetic+benchmark data taillard | K24: ML | L24: Decision Transformer, Imitation Learning | M24: Germany | N24: 2025 | O24: Not specified | P24: Scheduling | Q24: Job Shop Scheduling | R24: Makespan | S24: Improved scheduling | U24: WaubertdePuiseau2025Applying | V24: Yes
A25: P1 | B25: 2025_smart_scheduling_of_hanging_workshop_via_digital_twin_and_deep_reinforcement_learning | C25: Smart scheduling of hanging workshop via digital twin and deep reinforcement learning | D25: https://doi.org/10.1007/s10696-024-09543-z | E25: No | F25: L2 | G25: benchmark+scenario | H25: static evaluation | I25: simulation | J25: synthetic+ benchmark mk (Brandimarte 1993) and la (Hurink et al. 1994) | K25: DT, RL | M25: China | N25: 2025 | O25: Not specified | P25: Scheduling | Q25: Flexible Job Shop Scheduling | R25: Makespan | S25: Improved scheduling | U25: Pan2025Smart | V25: Yes
A26: P1 | B26: 2025_a_multi-action_deep_reinforcement_learning_based_on_bilstm_for_flexible_job_shop_scheduling_problem_with_tight_time | C26: A Multi-Action Deep Reinforcement Learning Based on BiLSTM for Flexible Job Shop Scheduling Problem with Tight Time | D26: https://doi.org/10.1145/3709026.3709038 | E26: No | F26: L2 | G26: scenario | H26: static evaluation | I26: simulation | J26: Synthetic | K26: RL | L26: Decision Transformer | M26: China | N26: 2025 | O26: Not specified | P26: Scheduling | Q26: Flexible Job Shop Scheduling | R26: Tardiness | S26: Improved scheduling, minimising waiting time | U26: Wang2025A | V26: Yes
A27: P1 | B27: 2025_a_novel_mixed_integer_programming_model_with_precedence_relation-based_decision_variables_for_non-cyclic_scheduling_of_cluster_tools | C27: A Novel Mixed Integer Programming Model with Precedence Relation-Based Decision Variables for Non-Cyclic Scheduling of Cluster Tools | D27: https://doi.org/10.1109/TASE.2024.3386562 | E27: No | F27: L1 | G27: Scenarios | I27: static evaluation | J27: Synthetic | K27: CPS | L27: Petri Net, DES | M27: South Korea | N27: 2025 | O27: Semiconductor | P27: Scheduling | Q27: No | R27: Makespan | S27: Improved Scheduling | U27: Ahn2025A | V27: Yes
A28: P1 | B28: 2025_a_hierarchical_multi-action_deep_reinforcement_learning_method_for_dynamic_distributed_job-shop_scheduling_problem_with_job_arrivals | C28: A Hierarchical Multi-Action Deep Reinforcement Learning Method for Dynamic Distributed Job-Shop Scheduling Problem with Job Arrivals | D28: https://doi.org/10.1109/TASE.2024.3380644 | E28: No | F28: L2 | G28: scenario+industrial case study | H28: scenario | I28: simulation | J28: synthetic+industrial data | K28: MAS, RL | L28: MARL | M28: China | N28: 2025 | O28: Automotive | P28: Scheduling | Q28: Dynamic Distributed Job Shop Scheduling | R28: Robustness --> makespan and machine idle time (MIT) | S28: Handling uncertain disturbance from job arrivals | U28: Huang2025A | V28: Yes
A29: P1 | B29: 2025_hybrid_task_scheduling_in_cloud_manufacturing_with_sparse-reward_deep_reinforcement_learning | C29: Hybrid Task Scheduling in Cloud Manufacturing With Sparse-Reward Deep Reinforcement Learning | D29: https://doi.org/10.1109/TASE.2024.3371250 | E29: No | F29: L2 | G29: indsutrial case study | H29: simulation | I29: simulation | J29: industrial data+synthetic+benchmark data (Not typically used). | K29: RL | L29: MDP | M29: China | N29: 2025 | O29: Not specified | P29: Scheduling | Q29: No | R29: Makespan | S29: Minimising Makespan by solving hybrid task scheduling problem | U29: Wang2025Hybrid | V29: Yes
A30: P1 | B30: 2025_real-time_decision-support_system_for_high-mix_low-volume_production_scheduling_in_industry_4.0 | C30: Real-Time Decision-Support System for High-Mix Low-Volume Production Scheduling in Industry 4.0 | D30: https://doi.org/10.3390/PR8080912 | E30: No | F30: L2 | G30: simulation+survey study+risk analysis | I30: simulation | J30: synthetic+industrial data (survey) | K30: CPS | M30: Hungary | N30: 2025 | O30: Not specified | P30: Scheduling | Q30: No | R30: Makespan | S30: Minimising makespan by consindering the results of risks analysis of HMLV manufacturing | U30: Long2025RealTime | V30: Yes
A31: P1 | B31: 2022_job_shop_rescheduling_with_rework_and_reconditioning_in_industry_4.0:_an_event-driven_approach | C31: Job shop rescheduling with rework and reconditioning in Industry 4.0: an event-driven approach | D31: https://doi.org/10.1007/s00170-021-08163-3 | E31: No | F31: L2 | G31: scenario+simulation | I31: simulation | J31: synthetic | K31: CPS | L31: PPO | M31: Colombia | N31: 2022 | O31: Not specified | P31: Scheduling | Q31: Job Shop Scheduling | R31: Robustness --> Relative Peformance Difference (RPD) + stability metric | S31: Improving rescheduling | U31: Meja2022Job | V31: Yes
A32: P1 | B32: 2025_joint_optimization_of_maintenance_and_quality_inspection_for_multi-stage_manufacturing_system_based_on_genetic_reinforcement_learning | C32: Joint Optimization of Maintenance and Quality Inspection for Multi-Stage Manufacturing System Based on Genetic Reinforcement Learning | D32: https://doi.org/10.1002/qre.70027 | E32: Yes | F32: L2 | G32: simulation+scenario | I32: simulation | J32: synthetic | K32: CPS, RL | L32: DQN, Genetic Algorithm, Metaheuristic | M32: China | N32: 2025 | O32: Not specified | P32: Product quality | Q32: No | R32: robustness --> costs (maintenance, inspection, buffer penalties) and performance indcators Machine reliability + product quality (probability of producing defective items) | S32: Optimising buffer stock, quality inspection | U32: Wang2025Joint | V32: Yes
A33: P1 | B33: 2025_natural_language-driven_production_planning:_integrating_large_language_models_with_automatic_simulation_model_generation_in_manufacturing_systems | C33: Natural language-driven production planning: integrating large language models with automatic simulation model generation in manufacturing systems | D33: https://doi.org/10.1007/s10845-025-02732-z | E33: Yes | F33: L2 | G33: none of the above | H33: none/Other | I33: simulation | J33: synthetic | K33: ML | L33: LLM, DES | M33: Italy | N33: 2025 | O33: Not specified | P33: Simulation generation | Q33: No | R33: Machine utilisation | S33: Improving resource utilisation, bottleneck identification, and production scheduling | U33: Elbasheer2025Natural | V33: YesNo
A34: P1 | B34: 2025_a_refined_two-stage_fuzzy_hybrid_decision_making_support_framework_for_enhancing_logistics_and_manufacturing_integration | C34: A refined two-stage fuzzy hybrid decision making support framework for enhancing logistics and manufacturing integration | D34: https://doi.org/10.1016/j.aei.2025.103780 | E34: Yes | F34: L3 | G34: industrial case study+sensitivity analysis | H34: scenario | I34: static evaluation | J34: industrial data | K34: RL | L34: Fuzzy Methods, MCDM | M34: China | N34: 2025 | O34: Not specified | P34: Logistics | Q34: No | R34: Robustness (resilience) --> MULTIMOORA score (ranking-based) | S34: Improving resilience in supply chain | U34: Yang2025Refined | V34: yes
A35: P1 | B35: 2023_a_multi-objective_bi-level_leader-follower_joint_optimization_for_concurrent_design_of_product_family_and_assembly_system | C35: A multi-objective Bi-level leader-follower joint optimization for concurrent design of product family and assembly system | D35: https://doi.org/10.1016/j.cie.2023.109035 | E35: Yes | F35: L2 | G35: industrial case study+scenario | H35: simulation | I35: static evaluation | J35: synthetic | L35: Mathematical Programming, Genetic Algorithm, Simulation, Metaheuristic, Optimisation | M35: Australia | N35: 2023 | O35: Not specified | P35: Product family modularization | Q35: No | R35: Makespan | S35: Maximising profit | U35: Hossain2023Multiobjective | V35: Yes
A36: P1 | B36: 2025_a_deep_reinforcement_learning_driven_bi-population_evolutionary_optimization_for_precast_concrete_scheduling_with_production_transportation | C36: A deep reinforcement learning driven bi-population evolutionary optimization for precast concrete scheduling with production transportation | D36: https://doi.org/10.1016/j.cie.2025.111354 | E36: Yes | F36: L3 | G36: scenario | I36: static evaluation | J36: synthetic | K36: RL | L36: Evolutionary Algorithm | M36: China | N36: 2025 | O36: Precast concrete | P36: Scheduling | Q36: Distributed flexible job SSP | R36: Makespan / Energy efficiency | S36: Improving these metrics through B-DQN | U36: Du2025Deep | V36: yes
A37: P1 | B37: 2025_dynamic_integrated_process_planning_and_scheduling_under_multi-resource_constraints_in_workshops_with_reconfigurable_manufacturing_cells:_a_novel_hyper-heuristic_approach | C37: Dynamic integrated process planning and scheduling under multi-resource constraints in workshops with reconfigurable manufacturing cells: a novel hyper-heuristic approach | D37: https://doi.org/10.1016/j.eswa.2025.128337 | E37: Yes | F37: L1 | G37: scenario+simulation | I37: simulation | J37: synthetic | K37: RMS | L37: Hyper-Heuristic, Heuristic | M37: China | N37: 2025 | O37: Not specified | P37: Scheduling | Q37: No | R37: Robustness --> makespan, total tardiness, total reconfiguraiton time, worker load balancing, equioment load balancing | S37: Adressing the dynamic integrated process planning and scheduling under multi-resrouce constraints in workshops with reconfigurable manufacturing cells problem | T37: I think this falls into L1 | U37: Guo2025Dynamic | V37: Yes
A38: P2 | B38: 2024_transitioning_trends_into_action:_a_simulation-based_digital_twin_architecture_for_enhanced_strategic_and_operational_decision-making | C38: Transitioning trends into action: A simulation-based Digital Twin architecture for enhanced strategic and operational decision-making | D38: https://doi.org/10.1016/j.cie.2024.110616 | E38: No | F38: L2 | G38: simulation+lab case study | I38: simulation | J38: lab data+synthetic | K38: DT, IoT | L38: Metaheuristic, DES | M38: Portugal | N38: 2024 | O38: Not specified | P38: Scheduling | Q38: No | R38: Makespan | S38: Enhance operational efficiency and facilitate adoption of the manufacturing as a service paradigm | U38: Santos2024Transitioning | V38: Yes
A39: P2 | B39: 2024_learning-enabled_flexible_job-shop_scheduling_for_scalable_smart_manufacturing | C39: Learning-enabled flexible job-shop scheduling for scalable smart manufacturing | D39: https://doi.org/10.1016/j.jmsy.2024.09.011 | E39: No | F39: L2 | G39: benchmark+scenario | H39: static evaluation | I39: simulation | J39: synthetic+Public benchmark Brandimarte | K39: AGV/AMR | L39: GNN | M39: South Korea | N39: 2024 | O39: Not specified | P39: Scheduling | Q39: Flexible Job Shop Scheduling | R39: Makespan | S39: Tackling the scale generalisation challenge of FJSSP | U39: Moon2024Learningenabled | V39: Yes
A40: P2 | B40: 2024_a_deep_reinforcement_learning_based_approach_for_dynamic_job_shop_scheduling_considering_variable_processing_time | C40: A deep reinforcement learning based approach for dynamic job shop scheduling considering variable processing time | D40: https://doi.org/10.1145/3690931.3690993 | E40: No | F40: L2 | G40: benchmark+scenario | H40: static evaluation | I40: simulation | J40: synthetic+Public benchmark ft06 Fisher | K40: RL | L40: MDP | M40: China | N40: 2024 | O40: Not specified | P40: Scheduling | Q40: Dynamic Job Shop Scheduling | R40: Makespan | S40: Improving scheduling | U40: Yang2024A | V40: Yes
...

Sheet Quantification Sheet
A1: Technology | B1: Number of papers | C1: Methods | D1: Number of Papers | H1: Metric | I1: Sources
A2: Reinforced Learning | B2: =SUMPRODUCT( --( ISNUMBER(SEARCH("RL"," "&'Cleaned Master sheet'!K1:K100002&" ")) + ISNUMBER(SEARCH("Reinforced learning",'Cleaned Master sheet'!K1:K100002)) > 0 ) ) -> 103 | C2: Reinforcement Learning | D2: =SUMPRODUCT(--(ISNUMBER(SEARCH(C2,'Cleaned Master sheet'!L1:L99996)))) -> 9 | G2: RQ4 | H2: Benchmark sets | I2: =TEXTJOIN(", ", TRUE, IF('Cleaned Master sheet'!I:I="Simulation", 'Cleaned Master sheet'!U:U,""))
A3: Machine Learning | B3: =SUMPRODUCT( --( ISNUMBER(SEARCH("ML"," "&'Cleaned Master sheet'!K1:K100002&" ")) + ISNUMBER(SEARCH("Machine learning",'Cleaned Master sheet'!K1:K100002)) > 0 ) ) -> 21 | C3: Multi-Agent RL | D3: =SUMPRODUCT(--(ISNUMBER(SEARCH(C3,'Cleaned Master sheet'!L2:L99997)))) -> 0 | H3: Simulation
A4: Artificial Intelligence | B4: =SUMPRODUCT( --( ISNUMBER(SEARCH("AI"," "&'Cleaned Master sheet'!K1:K100005&" ")) + ISNUMBER(SEARCH("Artificial Intelligence",'Cleaned Master sheet'!K1:K100005)) > 0 ) ) -> 11 | C4: Heuristics | D4: =SUMPRODUCT(--(ISNUMBER(SEARCH(C4,'Cleaned Master sheet'!L3:L99998)))) -> 0 | H4: Case studies | I4: =TEXTJOIN(", ", TRUE, IF('Cleaned Master sheet'!I1:I1001="simulation", 'Cleaned Master sheet'!U1:U1001, ""))
A5: Digital Twin | B5: =SUMPRODUCT( --( ISNUMBER(SEARCH("DT"," "&'Cleaned Master sheet'!K1:K100004&" ")) + ISNUMBER(SEARCH("Digital Twin",'Cleaned Master sheet'!K1:K100004)) > 0 ) ) -> 21 | C5: Metaheuristic | D5: =SUMPRODUCT(--(ISNUMBER(SEARCH(C5,'Cleaned Master sheet'!L4:L99999)))) -> 18 | H5: Real-world implementation
A6: Internet of Things | B6: =SUMPRODUCT( --( ISNUMBER(SEARCH("IoT"," "&'Cleaned Master sheet'!K1:K100002&" ")) + ISNUMBER(SEARCH("Internet of Thing",'Cleaned Master sheet'!K1:K100002)) > 0 ) ) -> 20 | C6: Genetic algorithm | D6: =SUMPRODUCT(--(ISNUMBER(SEARCH(C6,'Cleaned Master sheet'!L5:L100000)))) -> 21 | I6: =TEXTJOIN(", ", TRUE, IF(TRIM(LOWER('Cleaned Master sheet'!I1:I1001))="simulation", 'Cleaned Master sheet'!U1:U1001, "")) -> Bibtex ref, Ghasemi2022Demonstration, Herkes2022Using, Tremblet2022Predicting, Kim2022A, ElSayed2022Deep, Klar2022Scalability, Feng2022Predictive, He2022Simultaneous, Zhou2021Multiagent, Zhang2021Datadriven, Wang2021Evolutionary, Wan2021ArtificialIntelligenceDriven, Padovano2021A, Zhou2021Reinforcement, Glatt2021Modeling, Feng2020Simulation, Coito2020A, Chawalitanont2025Uncertaintyaware, Zhang2025MAMHSAN, Xiao2025Material, Duan2025A, Yuan2025Dynamic, WaubertdePuiseau2025Applying, Pan2025Smart, Wang2025A, Ahn2025A, Huang2025A, Wang2025Hybrid, Long2025RealTime, Meja2022Job, Wang2025Joint, Elbasheer2025Natural, Yang2025Refined, Hossain2023Multiobjective, Du2025Deep, Guo2025Dynamic, Santos2024Transitioning, Moon2024Learningenabled, Yang2024A, Nejati2024A, Yue2024Twostage, RangelMartnez2024A, Corra2024Rainbow, Tang2024Solving, He2024The, Wang2024Smart, Su2024Fast, Lu2024A, Lassoued2024Introducing, Pu2024MultiAgent, Huang2024An, SerranoRuiz2024Job, Wang2024Flexible, Zhao2025A, Li2025Demanddriven, Yoo2025Optimizing, Wang2025Inventory, Zeng2025Dynamic, Liu2025EFJSPIBDR, Canciglieri2025Smart, Wang2025Experience, Du2025GraphAugmented, Kochański2024Datadriven, Lefranc2024Enhancing, Petersen2024Multiobjective, Li2026Outoforder, Qu2023Selfdecision, Fragapane2020Increasing, Mahmood2021Production, Wang2023Job, Ghasemi2023Deep, Workneh2023Deep, Workneh2023Learning, Zhang2022Dynamic, Jiang2022A, Yang2022Realtime, Wang2022Solving, Yan2022Digital, Bencheikh2022An, Gdri2022Improving, He2022Joint, Zhang2022Dynamicb, Li2022Realtime, Li2025Evolutionary, Yuan2025Deep, Hu2025Dynamic, Shi2025Productionlogistics, Chen2025Optimizing, Yan2025A, Hong2025Cloudfogedge, Shi2024ProductionLogistics, Sun2024Research, Zhang2024Digital, He2024Deep, Xu2024Ab, Pereira2024Energy, Hou2024Deep, Zhang2024ExpertGuided, Lei2024LargeScale, Zhang2023Dynamic, Huang2023A, Xu2023Multiobjective, Song2023Flexible, Zhou2024Practical, Ding2025Deep, Zhang2025Optimization, Lee2025Cognitive, Zhong2025Flexible, Sherwin2025A, Li2025Energyaware, Rubel2025AgentBased, Tsao2020Energyefficient, Lee2020Idle, Golpira2020Smart, Wu2023Energyefficient, Xue2025Multiobjective, Bittencourt2025Simheuristic, Che2016Efficient, Li2024Unleashing, ZhangSprenger2024RTMN, Yu2024Design, Hoebert2023Knowledgedriven, Devanga2022Applied, Tanane2022Toward, Rubaiee2019An, Tian2024Balancing, Mahmoodi2024Datadriven, Kim2024Deep, Slot2023Versatile, Du2022Production, Senington2021Monte, Zhang2025Multiagent, Yan2025Deep, Zhang2025Integrated, Lyu2025Pathfinder, Yang2025Evolutionary, Ghaleb2021Realtime, Mao2025Job, Mahmoodi2025Predictive, Fang2020The, Han2020Research, Baltazar2020Prescriptive, Burggrf2020Performance, Peng2020The, Bemthuis2019An, Zhai2019Formulation, MndezHernndez2019A, Kuhnle2019Design, Gdri2019Data, Leusin2018Solving, Yang2022Research, Hu2025Graphbased, Hua2025Solving, Lee2025A, Echeverria2025Diverse, Elbasheer2024Leveraging, Rema2025Exploring, Zhou2025A, Zhang2024Ab, Yang2024Learning, PatalasMaliszewska2025AIDriven, Yan2025Ab, Kozjek2018Big, Ling2024Manufacturing, Senoner2023Addressing, Zhang2025Trusted, Zhang2025Digital, Zhang2025Digitala, Zhou2022Reinforcement, Zhai2022Predictive, Modesti2024Artificial, Wang2024Unified, Elsayed2021Deep, Yan2021Autonomous, Antons2024Designing, Liu2023A, Skr2023Optimization, Bubak2025An, Ouahabi2025Dynamic, Lee2025Ab, Ma2025Research, Li2025Ab, Flyckt2025Navigating, Yi2025Dynamic, Zeng2025PermutationInvariant, Wang2025MultiObjective, Zhong2025Solving, Salatiello2024Longsighted, Zhang2025Innovative, Choi2025Deep, Lan2026Knowledge, Yepes-borrero2026Unrelated, Kim2025Framework, Hou2025Learningbased, Cen2025Dual, Fu2025Hybrid, Wang2025Collaborative, Afari2025Datadriven, Vacchi2025Black, Li2025Generative, Urrea2025Hybrid, Li2025Realtime, Zheng2025Dynamic, Gong2023Collaborative, Cimino2024Enhancing
A7: Heuristics | B7: =SUMPRODUCT( --( ISNUMBER(SEARCH("Heuristics"," "&'Cleaned Master sheet'!K1:K100002&" ")) ) ) -> 0 | C7: Optimization | D7: =SUMPRODUCT(--(ISNUMBER(SEARCH(C7,'Cleaned Master sheet'!L6:L100001)))) -> 1
A8: Cyber Physical System | B8: =SUMPRODUCT( --( ISNUMBER(SEARCH("CPS"," "&'Cleaned Master sheet'!K1:K100002&" ")) + ISNUMBER(SEARCH("Cyber Physical System",'Cleaned Master sheet'!K1:K100002)) > 0 ) ) -> 17 | C8: Bayesian Learning | D8: =SUMPRODUCT(--(ISNUMBER(SEARCH(C8,'Cleaned Master sheet'!L7:L100002)))) -> 2
A9: Metaheuristics | B9: =SUMPRODUCT( --( ISNUMBER(SEARCH("Metaheuristic"," "&'Cleaned Master sheet'!K1:K100002&" ")) + ISNUMBER(SEARCH("GA",'Cleaned Master sheet'!K1:K100002)) > 0 ) ) -> 0 | C9: Graph Learning | D9: =SUMPRODUCT(--(ISNUMBER(SEARCH(C9,'Cleaned Master sheet'!L8:L100003)))) -> 0
A10: Robot | B10: =SUMPRODUCT( --( ISNUMBER(SEARCH("Robot"," "&'Cleaned Master sheet'!K1:K100002&" ")) + ISNUMBER(SEARCH("HRC",'Cleaned Master sheet'!K1:K100002)) > 0 ) ) -> 15 | C10: Multi-objective optimization | D10: =SUMPRODUCT(--(ISNUMBER(SEARCH(C10,'Cleaned Master sheet'!L9:L100004)))) -> 0
A11: Automated Guided Vehicle | B11: =SUMPRODUCT( --( ISNUMBER(SEARCH("AGV"," "&'Cleaned Master sheet'!K1:K100002&" ")) + ISNUMBER(SEARCH("Automated Guided Vehicle",'Cleaned Master sheet'!K1:K100002)) > 0 ) ) -> 14 | C11: Markov Decision Process | D11: =SUMPRODUCT(--(ISNUMBER(SEARCH(C11,'Cleaned Master sheet'!L10:L100005)))) -> 0
A12: Discrete Event Simulation | B12: =SUMPRODUCT( --( ISNUMBER(SEARCH("DES"," "&'Cleaned Master sheet'!K1:K100002&" ")) + ISNUMBER(SEARCH("Discrete Event Simulation",'Cleaned Master sheet'!K1:K100002)) > 0 ) ) -> 0 | C12: agv | D12: =SUMPRODUCT(--(ISNUMBER(SEARCH(C12,'Cleaned Master sheet'!L11:L100006)))) -> 0
A13: Edge Computing | B13: =SUMPRODUCT( --( ISNUMBER(SEARCH("EC"," "&'Cleaned Master sheet'!K1:K100002&" ")) + ISNUMBER(SEARCH("Edge Computing",'Cleaned Master sheet'!K1:K100002)) > 0 ) ) -> 6 | C13: Decision Transformers | D13: =SUMPRODUCT(--(ISNUMBER(SEARCH(C13,'Cleaned Master sheet'!L12:L100007)))) -> 0
A14: Multi-Agent System | B14: =SUMPRODUCT( --( ISNUMBER(SEARCH("MAS"," "&'Cleaned Master sheet'!K1:K100002&" ")) + ISNUMBER(SEARCH("multi-agent",'Cleaned Master sheet'!K1:K100002)) > 0 ) ) -> 7 | C14: Graph neural network | D14: =SUMPRODUCT(--(ISNUMBER(SEARCH(C14,'Cleaned Master sheet'!L13:L100008)))) -> 0
A15: CPLEX Solver | B15: 4 | C15: Deep Q-network | D15: =SUMPRODUCT(--(ISNUMBER(SEARCH(C15,'Cleaned Master sheet'!L14:L100009)))) -> 0
A16: Reconfigurable Manufacturing System | B16: =SUMPRODUCT( --( ISNUMBER(SEARCH("RMS"," "&'Cleaned Master sheet'!K1:K100002&" ")) + ISNUMBER(SEARCH("Reconfigurable Manufacturing System",'Cleaned Master sheet'!K1:K100002)) > 0 ) ) -> 3 | C16: PPO | D16: =SUMPRODUCT(--(ISNUMBER(SEARCH(C16,'Cleaned Master sheet'!L15:L100010)))) -> 22
A17: Mixed Integer Linear Programming | B17: =SUMPRODUCT( --( ISNUMBER(SEARCH("MILP"," "&'Cleaned Master sheet'!K1:K100002&" ")) + ISNUMBER(SEARCH("Mixed Integer Linear Programming",'Cleaned Master sheet'!K1:K100002)) > 0 ) ) -> 0 | C17: Tabu Search | D17: =SUMPRODUCT(--(ISNUMBER(SEARCH(C17,'Cleaned Master sheet'!L16:L100011)))) -> 3
A18: Predictive Maintenance | B18: =SUMPRODUCT( --( ISNUMBER(SEARCH("PM"," "&'Cleaned Master sheet'!K1:K100002&" ")) + ISNUMBER(SEARCH("Predictive Maintenance",'Cleaned Master sheet'!K1:K100002)) > 0 ) ) -> 0 | C18: Deep q-network | D18: =SUMPRODUCT(--(ISNUMBER(SEARCH(C18,'Cleaned Master sheet'!L17:L100012)))) -> 0
A19: Manufacturing Enterprise System | B19: =SUMPRODUCT( --( ISNUMBER(SEARCH("MES"," "&'Cleaned Master sheet'!K1:K100003&" ")) + ISNUMBER(SEARCH("Manufacturing Enterprise System",'Cleaned Master sheet'!K1:K100003)) > 0 ) ) -> 2 | C19: ioT | D19: =SUMPRODUCT(--(ISNUMBER(SEARCH(C19,'Cleaned Master sheet'!L18:L100013)))) -> 0
A20: Flexible Manufacturing System | B20: =SUMPRODUCT( --( ISNUMBER(SEARCH("FMS"," "&'Cleaned Master sheet'!K1:K100002&" ")) + ISNUMBER(SEARCH("Flexible Manufacturing System",'Cleaned Master sheet'!K1:K100002)) > 0 ) ) -> 2 | C20: MILP | D20: =SUMPRODUCT(--(ISNUMBER(SEARCH(C20,'Cleaned Master sheet'!L19:L100014)))) -> 7
A21: Gurobi Solver | B21: 1 | C21: monte carlo tree search | D21: =SUMPRODUCT(--(ISNUMBER(SEARCH(C21,'Cleaned Master sheet'!L20:L100015)))) -> 0
A22: Lingo Software | B22: 1 | C22: forecasting | D22: =SUMPRODUCT(--(ISNUMBER(SEARCH(C22,'Cleaned Master sheet'!L21:L100016)))) -> 3
A23: Autonomous Mobile Robot | B23: =SUMPRODUCT( --( ISNUMBER(SEARCH("AMR"," "&'Cleaned Master sheet'!K1:K100002&" ")) + ISNUMBER(SEARCH("Autonomous",'Cleaned Master sheet'!K1:K100002)) > 0 ) ) -> 14 | C23: Predictive maintenance | D23: =SUMPRODUCT(--(ISNUMBER(SEARCH(C23,'Cleaned Master sheet'!L22:L100017)))) -> 4

Sheet Extras
B1: key_id | C1: Title | D1: DOI | E1: Snowball (Yes/No) | F1: Manufacturing level (L0,L1,L2,L3/L4) | G1: Old Evaluation (Scenarios, Simulation, Case study,…) | H1: Primary Evaluation(s) | I1: Evaluation setting | J1: Data Source | K1: Technologies | L1: Methods | M1: Country | N1: Date | O1: Industry | P1: DSS focus | Q1: Job-shop variations | R1: Metrics | S1: Improvement goals or objectives (What they try to achieve) | T1: comments | U1: Bibtex ref | V1: Cited in survey? Yes/No | W1: Special/different papers notes for discussion
